<?xml version='1.0'?>
<sdf version='1.9'>
    <model name='floating_camera'>
        <gravity>false</gravity>
        <static>true</static>
        <link name="base_link" gravity="0 0 0">
            <pose>0 0 0 0 0 0</pose>
        </link>
        <link name="camera_link">
            <inertial>
                <mass>0.01</mass>
                <inertia>
                    <ixx>0.00001</ixx>
                    <ixy>0</ixy>
                    <ixz>0</ixz>
                    <iyy>0.00001</iyy>
                    <iyz>0</iyz>
                    <izz>0.00001</izz>
                </inertia>
            </inertial>
            <gravity>false</gravity>
            <pose degrees="true">0 0 0 0 180 0</pose>
            <visual name="camera_visual">
                <pose>0 0 0.02 0 0 0</pose>
                <geometry>
                <cylinder>
                    <radius>0.025</radius>
                    <length>0.050</length>
                </cylinder>
                </geometry>
            </visual>
            <sensor name="floating_camera" type="camera">
            <pose degrees="true">0 0 0 0 -90 0</pose>
            <camera>
                <horizontal_fov>1.57</horizontal_fov>
                <image>
                <width>640</width>
                <height>480</height>
                </image>
                <clip>
                <near>0.05</near>
                <far>15000</far>
                </clip>
            </camera>
            <always_on>1</always_on>
            <update_rate>3</update_rate>
            <visualize>0</visualize>
            </sensor>
        </link>
        <joint name="camera_joint" type="prismatic">
            <parent>base_link</parent>
            <child>camera_link</child>
        </joint>
      <plugin
        filename="gz-sim-pose-publisher-system"
        name="gz::sim::systems::PosePublisher">
        <publish_link_pose>false</publish_link_pose>
        <publish_collision_pose>false</publish_collision_pose>
        <publish_visual_pose>false</publish_visual_pose>
        <publish_nested_model_pose>false</publish_nested_model_pose>
      </plugin>
    </model>
</sdf>
